Workbook
Name DATA3: #REF!
Name DATA3: #REF!

Sheet HC_0220
A1: No | B1: SAP ID | C1: Name | D1: PA | E1: PA Text | F1: Sub Area | G1: Sub Area Text | H1: Cost Center | I1: OU | J1: OU Text | K1: Position | L1: Postion Text | M1: Level | N1: Mapping | O1: Usernama | P1: Email
A2: 1 | B2: 10049945 | C2: Josua Silalahi | D2: 5502 | E2: Adindo Hutani Lestari (KLT) | F2: 0210 | G2: MO (AHL) | H2: F211192001 | I2: 13000117 | J2: AHL-Finance & Accounting | K2: 70352934 | L2: Asst Barge Checker, FATC | M2: Asst | N2: Overhead | O2: #N/A | P2: #N/A
A3: =+A2+1 -> 2 | B3: 10054896 | C3: Anton | D3: 5502 | E3: Adindo Hutani Lestari (KLT) | F3: 0210 | G3: MO (AHL) | H3: F211195003 | I3: 13000121 | J3: AHL-PA & GA HO,KDU | K3: 70481457 | L3: Mandor GA, HR | M3: Non Staff | N3: Overhead | O3: #N/A | P3: #N/A
A4: =+A3+1 -> 3 | B4: 10039906 | C4: Maikel Pamassangan | D4: 5502 | E4: Adindo Hutani Lestari (KLT) | F4: 0211 | G4: Sebakis | H4: F211106015 | I4: 70542936 | J4: AHL-QC Plantation Sebakis | K4: 70542947 | L4: Mandor QA, PQA & PQC | M4: Non Staff | N4: Overhead | O4: #N/A | P4: #N/A
A5: =+A4+1 -> 4 | B5: 10046771 | C5: Julius Lepong | D5: 5502 | E5: Adindo Hutani Lestari (KLT) | F5: 0211 | G5: Sebakis | H5: F211106015 | I5: 70542936 | J5: AHL-QC Plantation Sebakis | K5: 70542949 | L5: Mandor QA, PQA & PQC | M5: Non Staff | N5: Overhead | O5: #N/A | P5: #N/A
A6: =+A5+1 -> 5 | B6: 10054890 | C6: Nirgayani | D6: 5502 | E6: Adindo Hutani Lestari (KLT) | F6: 0211 | G6: Sebakis | H6: F211106015 | I6: 70542936 | J6: AHL-QC Plantation Sebakis | K6: 70542984 | L6: Mandor QA, PQA & PQC | M6: Non Staff | N6: Overhead | O6: #N/A | P6: #N/A
A7: =+A6+1 -> 6 | B7: 10023239 | C7: Miftakul Arifin | D7: 5502 | E7: Adindo Hutani Lestari (KLT) | F7: 0211 | G7: Sebakis | H7: F211406003 | I7: 13000139 | J7: AHL-Nursery Sebakis, KDU | K7: 13000956 | L7: Field Asst, Nursery | M7: Asst | N7: Overhead | O7: #N/A | P7: #N/A
A8: =+A7+1 -> 7 | B8: 10054681 | C8: Hariyadi | D8: 5502 | E8: Adindo Hutani Lestari (KLT) | F8: 0211 | G8: Sebakis | H8: F211406003 | I8: 13000139 | J8: AHL-Nursery Sebakis, KDU | K8: 13000815 | L8: Field Asst, Nursery | M8: Asst | N8: Overhead | O8: #N/A | P8: #N/A
A9: =+A8+1 -> 8 | B9: 10053696 | C9: Budi Widiantoro | D9: 5502 | E9: Adindo Hutani Lestari (KLT) | F9: 0211 | G9: Sebakis | H9: F211406003 | I9: 13000139 | J9: AHL-Nursery Sebakis, KDU | K9: 70223748 | L9: Field Mandor, Nursery | M9: Non Staff | N9: Overhead | O9: #N/A | P9: #N/A
A10: =+A9+1 -> 9 | B10: 10024999 | C10: DT.Muhammad Alias | D10: 5502 | E10: Adindo Hutani Lestari (KLT) | F10: 0211 | G10: Sebakis | H10: F211406004 | I10: 13000138 | J10: AHL-Plantation Sebakis, K | K10: 70145592 | L10: Field Mandor, Plantation | M10: Non Staff | N10: Overhead | O10: #N/A | P10: #N/A
A11: =+A10+1 -> 10 | B11: 10015909 | C11: Andi Lasemang | D11: 5502 | E11: Adindo Hutani Lestari (KLT) | F11: 0211 | G11: Sebakis | H11: F211406004 | I11: 13000138 | J11: AHL-Plantation Sebakis, K | K11: 70145547 | L11: Field Mandor, Plantation | M11: Non Staff | N11: Overhead | O11: #N/A | P11: #N/A
A12: =+A11+1 -> 11 | B12: 10023205 | C12: Muh.Yunus | D12: 5502 | E12: Adindo Hutani Lestari (KLT) | F12: 0211 | G12: Sebakis | H12: F211406004 | I12: 13000138 | J12: AHL-Plantation Sebakis, K | K12: 13000962 | L12: Field Mandor, Plantation | M12: Non Staff | N12: Overhead | O12: #N/A | P12: #N/A
A13: =+A12+1 -> 12 | B13: 10023206 | C13: Robet Sanjaya Kasim | D13: 5502 | E13: Adindo Hutani Lestari (KLT) | F13: 0211 | G13: Sebakis | H13: F211406004 | I13: 13000138 | J13: AHL-Plantation Sebakis, K | K13: 70138666 | L13: Field Mandor, Plantation | M13: Non Staff | N13: Overhead | O13: #N/A | P13: #N/A
A14: =+A13+1 -> 13 | B14: 10027427 | C14: Adang Supriadi | D14: 5502 | E14: Adindo Hutani Lestari (KLT) | F14: 0211 | G14: Sebakis | H14: F211406004 | I14: 13000138 | J14: AHL-Plantation Sebakis, K | K14: 70163937 | L14: Field Mandor, Plantation | M14: Non Staff | N14: Overhead | O14: #N/A | P14: #N/A
... A624: =+A623+1 -> 623 | B624: 10047592 | C624: Gunawan | D624: 5502 | E624: Adindo Hutani Lestari (KLT) | F624: 0212 | G624: Sembakung | H624: F211306007 | I624: 13000146 | J624: AHL-Planning Sembakung, K | K624: 13000844 | L624: Mandor Inventory, Planning | M624: Non Staff | N624: Overhead | O624: #N/A | P624: #N/A
A625: =+A624+1 -> 624 | B625: 10015453 | C625: Zuraidah | D625: 5528 | E625: ITCI Hutani Manunggal | F625: 0250 | G625: MO (IHM) | H625: F110191001 | I625: 13000082 | J625: IHM-Operational MO, KF | K625: 13000422 | L625: Secretary, GMO | M625: Asst | N625: Overhead | O625: Zuraidah | P625: Zuraidah@d1.lcl
A626: =+A625+1 -> 625 | B626: 10054873 | C626: Zulthan Aldogeri | D626: 5502 | E626: Adindo Hutani Lestari (KLT) | F626: 0210 | G626: MO (AHL) | H626: F211196008 | I626: 70166082 | J626: AHL-EHFS & Certification | K626: 70273628 | L626: Document Controller, Sustainability | M626: Asst | N626: Overhead | O626: Zulthan_Aldogeri | P626: Zulthan_Aldogeri@d1.lcl
A627: =+A626+1 -> 626 | B627: 10062564 | C627: Zulfidar Adam | D627: 5528 | E627: ITCI Hutani Manunggal | F627: 0250 | G627: MO (IHM) | H627: F110106005 | I627: 13000085 | J627: IHM-Road Maintenance & In | K627: 70484891 | L627: Manager, Infra & Road Maintenance | M627: Manager & Up | N627: Overhead | O627: Zulfidar_Adam | P627: Zulfidar_Adam@itci-hutani.com
A628: =+A627+1 -> 627 | B628: 10070310 | C628: Wan Zhitao | D628: 5590 | E628: Balikpapan Chip Lestari | F628: 0220 | G628: Teluk Waru | H628: C110001001 | I628: 70092779 | J628: KCM-Project, KDU | K628: 13001051 | L628: Askep Coordinator, Project | M628: IS | N628: Overhead | O628: ZhiTao_Wan | P628: ZhiTao_Wan@balikpapanchip.com
A629: =+A628+1 -> 628 | B629: 10043809 | C629: Zaky Mubarak | D629: 6208 | E629: Kalimantan Prima Services Ind. | F629: 0200 | G629: Balikpapan | H629: M200297001 | I629: 13000006 | J629: KPSI-Procurement,KDU | K629: 70143287 | L629: Sr. Buyer, Procurement | M629: Asst | N629: Overhead | O629: Zaky_Mubarak | P629: Zaky_Mubarak@kalimantan-prima.com
A630: =+A629+1 -> 629 | B630: 10034835 | C630: Zainul Mirza | D630: 5528 | E630: ITCI Hutani Manunggal | F630: 0250 | G630: MO (IHM) | H630: F110195003 | I630: 13000090 | J630: IHM-HR Operation MO, KF | K630: 13000510 | L630: Manager ER & IR, HR | M630: Manager & Up | N630: Overhead | O630: Zainul_Mirza | P630: Zainul_Mirza@itci-hutani.com
A631: =+A630+1 -> 630 | B631: 10024507 | C631: Yuyu Wahyuddin | D631: 6208 | E631: Kalimantan Prima Services Ind. | F631: 0209 | G631: Pontianak | H631: O118001001 | I631: 70357997 | J631: KPSI-Operation Kalbar, KD | K631: 13000242 | L631: Manager, Wood Supply | M631: Manager & Up | N631: Overhead | O631: Yuyu_wahyuddin | P631: Yuyu_Wahyuddin@kalimantan-prima.com
A632: =+A631+1 -> 631 | B632: 10062487 | C632: Yurita Luhat | D632: 5502 | E632: Adindo Hutani Lestari (KLT) | F632: 0210 | G632: MO (AHL) | H632: F211196001 | I632: 13000119 | J632: AHL-SSL & CD Ho, KDU | K632: 70554935 | L632: Admin, SSL | M632: Non Staff | N632: Overhead | O632: Yurita_Luhat | P632: Yurita_Luhat@ptadindo.com
A633: =+A632+1 -> 632 | B633: 10070109 | C633: Yunita Takahindangeng | D633: 5528 | E633: ITCI Hutani Manunggal | F633: 0260 | G633: Terunen | H633: F110195002 | I633: 70124065 | J633: IHM-L&D Terunen, KF | K633: 70199471 | L633: Assistant Trainee, L&D | M633: TRN C | N633: Overhead | O633: Yunita_T | P633: Yunita_T@d1.lcl
A634: =+A633+1 -> 633 | B634: 10015549 | C634: Yulius Barru | D634: 5528 | E634: ITCI Hutani Manunggal | F634: 0280 | G634: Senoni | H634: F110406004 | I634: 13000105 | J634: IHM-Plantation Senoni, KF | K634: 70231116 | L634: Field Asst, Plantation | M634: Asst | N634: Overhead | O634: Yulius_Barru | P634: Yulius_Barru@d1.lcl
A635: =+A634+1 -> 634 | B635: 10063654 | C635: Yuliana Shermina Taalendo | D635: 5502 | E635: Adindo Hutani Lestari (KLT) | F635: 0210 | G635: MO (AHL) | H635: F211196008 | I635: 70166082 | J635: AHL-EHFS & Certification | K635: 70561327 | L635: Asst Fire & Safety, Sustainability | M635: Asst | N635: Overhead | O635: Yuliana_Taalendo | P635: Yuliana_Taalendo@ptadindo.com
A636: =+A635+1 -> 635 | B636: 10062329 | C636: Yuli Aristianto | D636: 5528 | E636: ITCI Hutani Manunggal | F636: 0250 | G636: MO (IHM) | H636: F110191001 | I636: 13000082 | J636: IHM-Operational MO, KF | K636: 70143991 | L636: External Relations, SSL | M636: Manager & Up | N636: Overhead | O636: Yuli_Aristianto | P636: Yuli_Aristianto@ptgmservices.com
... A901: =+A900+1 -> 900 | B901: 10057219 | C901: Ismail Soleh Batu Bara | D901: 5502 | E901: Adindo Hutani Lestari (KLT) | F901: 0212 | G901: Sembakung | H901: F211195002 | I901: 13000116 | J901: AHL-Learning & Developmen | K901: 70555793 | L901: Asst, L&D | M901: Asst | N901: Overhead | O901: Ismail_Batubara | P901: Ismail_Batubara@d1.lcl
A902: 1 | B902: 10025133 | C902: Irene M.Simamora | D902: 5502 | E902: Adindo Hutani Lestari (KLT) | F902: 0200 | G902: Balikpapan | H902: F211192001 | I902: 13000117 | J902: AHL-Finance & Accounting | K902: 70542940 | L902: Sr. Officer F&A, FATC | M902: Asst | N902: Overhead | O902: Irene_simamora | P902: Irene_Simamora@ptadindo.com
A903: =+A902+1 -> 2 | B903: 10058440 | C903: Irene Gunawan | D903: 5528 | E903: ITCI Hutani Manunggal | F903: 0200 | G903: Balikpapan | H903: F110195003 | I903: 13000090 | J903: IHM-HR Operation MO, KF | K903: 70143309 | L903: Superintendent Payroll, HR | M903: Askep | N903: Overhead | O903: Irene_Gunawan | P903: Irene_Gunawan@itci-hutani.com
A904: =+A903+1 -> 3 | B904: 10015529 | C904: Iqbal Marciano | D904: 5528 | E904: ITCI Hutani Manunggal | F904: 0270 | G904: Sepaku | H904: F110396008 | I904: 70542654 | J904: IHM-Sustainability Sepaku | K904: 13000721 | L904: Fire Guard, Sustainability | M904: Asst | N904: Overhead | O904: Iqbal_marciano | P904: Iqbal_Marciano@d1.lcl
A905: =+A904+1 -> 4 | B905: 10033668 | C905: Indra Pranata | D905: 5528 | E905: ITCI Hutani Manunggal | F905: 0260 | G905: Terunen | H905: F110195002 | I905: 70124065 | J905: IHM-L&D Terunen, KF | K905: 70406893 | L905: Askep, L&D | M905: Askep | N905: Overhead | O905: Indra_Pranata | P905: Indra_Pranata@d1.lcl
A906: =+A905+1 -> 5 | B906: 10058383 | C906: Indah Setiadewi | D906: 5528 | E906: ITCI Hutani Manunggal | F906: 0200 | G906: Balikpapan | H906: F110196001 | I906: 70131880 | J906: IHM-SSL & Legal MO, KF | K906: 70143296 | L906: Sr. Officer, SSL | M906: Asst | N906: Overhead | O906: Indah_setiadewi | P906: Indah_Setiadewi@itci-hutani.com
A907: =+A906+1 -> 6 | B907: 10037678 | C907: Inawan Choiril Purnomo | D907: 5528 | E907: ITCI Hutani Manunggal | F907: 0260 | G907: Terunen | H907: F110206002 | I907: 13000099 | J907: IHM-Common Service Terune | K907: 70094494 | L907: Admin PA & GA, HR | M907: Non Staff | N907: Overhead | O907: Inawan_Choiril | P907: Inawan_Choiril@d1.lcl
A908: =+A907+1 -> 7 | B908: 10049284 | C908: Iman Irawan | D908: 5528 | E908: ITCI Hutani Manunggal | F908: 0250 | G908: MO (IHM) | H908: F110106007 | I908: 13000083 | J908: IHM-Planning MO, KF | K908: 13000575 | L908: Sr. Asst GCS, Planning | M908: Asst | N908: Overhead | O908: Iman_Irawan | P908: Iman_Irawan@d1.lcl
A909: =+A908+1 -> 8 | B909: 10021557 | C909: Imam Pudjadi | D909: 5528 | E909: ITCI Hutani Manunggal | F909: 0260 | G909: Terunen | H909: F110297002 | I909: 13000099 | J909: IHM-Common Service Terune | K909: 70116020 | L909: Asst, Logistic | M909: Asst | N909: Overhead | O909: Imam_pudjadi | P909: Imam_Pudjadi@d1.lcl
A910: =+A909+1 -> 9 | B910: 10016210 | C910: Ilham Sinaga | D910: 5502 | E910: Adindo Hutani Lestari (KLT) | F910: 0210 | G910: MO (AHL) | H910: F211195002 | I910: 13000116 | J910: AHL-Learning & Developmen | K910: 70141895 | L910: HE Trainer, L&D | M910: Asst | N910: Overhead | O910: Ilham_sinaga | P910: Ilham_Sinaga@d1.lcl
A911: =+A910+1 -> 10 | B911: 10015905 | C911: Ilham Pansuri | D911: 5502 | E911: Adindo Hutani Lestari (KLT) | F911: 0211 | G911: Sebakis | H911: F211495003 | I911: 13000140 | J911: AHL-Common Service Sebaki | K911: 13000942 | L911: Asst, Logistic | M911: Asst | N911: Overhead | O911: Ilham_Pansuri | P911: Ilham_Pansuri@d1.lcl
A912: =+A911+1 -> 11 | B912: 10043820 | C912: Ika Anugrah Wardhani | D912: 5528 | E912: ITCI Hutani Manunggal | F912: 0250 | G912: MO (IHM) | H912: F110196001 | I912: 70131880 | J912: IHM-SSL & Legal MO, KF | K912: 70212407 | L912: Admin Legal, SSL | M912: Non Staff | N912: Overhead | O912: Ika_Wardhani | P912: Ika_Wardhani@d1.lcl
A913: =+A912+1 -> 12 | B913: 10016074 | C913: Ignatius Karamoy | D913: 5528 | E913: ITCI Hutani Manunggal | F913: 0270 | G913: Sepaku | H913: F110397002 | I913: 13000104 | J913: IHM-Common Service Sepaku | K913: 70353250 | L913: Sr. Asst, Logistic | M913: Asst | N913: Overhead | O913: Ignatius_karamoy | P913: Ignatius_Karamoy@d1.lcl
...

Sheet Sheet2
A1: ID | B1: Fullname | C1: Lookup | D1: Username | E1: Email | F1: Phone | G1: Company | H1: Type | I1: Active
A2: 50 | B2: Robin Smith | C2: =VLOOKUP("*"&B:B&"*",HC_0220!C:C,1,FALSE) -> Robin Smith Susenathan Vincent | D2: Robin_Smith | E2: Robin_Smith@ptadindo.com | F2: 86252, 77 2142 | G2: AHL | H2: User | I2: 1
A3: 163 | B3: Achmad Fauzi | C3: =VLOOKUP("*"&B:B&"*",HC_0220!C:C,1,FALSE) -> Achmad Fauzi | D3: Achmad_Fauzi | E3: Achmad_Fauzi@itci-hutani.com | G3: AHL | H3: User | I3: 1
A4: 205 | B4: Yosep Dandiyanto | C4: =VLOOKUP("*"&B:B&"*",HC_0220!C:C,1,FALSE) -> Yosep Dandiyanto Deku | D4: Yosep_dandiyanto | E4: Yosep_Dandiyanto@ptadindo.com | F4: 86255, 153 | G4: AHL | H4: User | I4: 1
A5: 230 | B5: Lidya Kartini Gultom | C5: =VLOOKUP("*"&B:B&"*",HC_0220!C:C,1,FALSE) -> #N/A | D5: Lidya_Gultom | E5: Lidya_Gultom@d1.lcl | G5: AHL | H5: User | I5: 1
A6: 259 | B6: Hariganesh Segar | C6: =VLOOKUP("*"&B:B&"*",HC_0220!C:C,1,FALSE) -> Hariganesh Segar | D6: Hariganesh_Segar | E6: Hariganesh_Segar@ptadindo.com | G6: AHL | H6: User | I6: 1
A7: 338 | B7: Julkipli | C7: Julkifli | D7: Julkipli | E7: Julkipli@d1.lcl | F7: 86252, 402 | G7: AHL | H7: User | I7: 1
A8: 339 | B8: Leo Petrus Sinaga | C8: =VLOOKUP("*"&B:B&"*",HC_0220!C:C,1,FALSE) -> Leo Petrus Sinaga | D8: Leo_Sinaga | E8: Leo_Sinaga@d1.lcl | G8: AHL | H8: User | I8: 1
A9: 341 | B9: Nia Christi Rahayu | C9: =VLOOKUP("*"&B:B&"*",HC_0220!C:C,1,FALSE) -> Nia Christi Rahayu | D9: Nia_Rahayu | E9: Nia_Rahayu@d1.lcl | F9: 86252, 402 | G9: AHL | H9: User | I9: 1
A10: 342 | B10: Gerry Prasetyo | C10: =VLOOKUP("*"&B:B&"*",HC_0220!C:C,1,FALSE) -> Gerry Prasetyo | D10: Gerry_Prasetyo | E10: Gerry_Prasetyo@d1.lcl | F10: 86252, 401 | G10: AHL | H10: User | I10: 1
A11: 343 | B11: Yohanes Sonne | C11: =VLOOKUP("*"&B:B&"*",HC_0220!C:C,1,FALSE) -> Yohanes Sonne | D11: Yohanes_Sonne | E11: Yohanes_Sonne@d1.lcl | F11: 86252 202 | G11: AHL | H11: User | I11: 1
A12: 344 | B12: Jainudin | C12: =VLOOKUP("*"&B:B&"*",HC_0220!C:C,1,FALSE) -> Jainudin | D12: Jainudin | E12: Jainudin@d1.lcl | G12: AHL | H12: User | I12: 1
A13: 345 | B13: Kristian Tri Hardono | C13: =VLOOKUP("*"&B:B&"*",HC_0220!C:C,1,FALSE) -> Kristian Tri Hardono | D13: Kristian_Hardono | E13: Kristian_Hardono@d1.lcl | F13: 86252, 402 | G13: AHL | H13: User | I13: 1
A14: 346 | B14: Ashar | C14: #N/A | D14: Ashar | E14: Ashar@d1.lcl | G14: AHL | H14: User | I14: 1
A15: 347 | B15: Amri Situmorang | C15: Amri Triharsono Sunandar Situmorang | D15: Amri_Situmorang | E15: Amri_Situmorang@d1.lcl | G15: AHL | H15: User | I15: 1
A16: 348 | B16: Endang Yustisari Bara | C16: =VLOOKUP("*"&B:B&"*",HC_0220!C:C,1,FALSE) -> Endang Yustisari Bara | D16: Endang_Bara | E16: Endang_Bara@d1.lcl | F16: 86252, 302 | G16: AHL | H16: User | I16: 1
A17: 349 | B17: Ronald Edwin Neman | C17: Ronald Neman | D17: Ronald_en | E17: Ronald_en@ptadindo.com | F17: 86252, 171 | G17: AHL | H17: User | I17: 1
A18: 350 | B18: Zico Rohandy Aris M | C18: =VLOOKUP("*"&B:B&"*",HC_0220!C:C,1,FALSE) -> #N/A | D18: Zico_Rohandy | E18: Zico_Rohandy@d1.lcl | F18: 86252 202 | G18: AHL | H18: User | I18: 1
A19: 351 | B19: Freddy Hutagalung | C19: =VLOOKUP("*"&B:B&"*",HC_0220!C:C,1,FALSE) -> Freddy Hutagalung | D19: Freddy_hutagalung | E19: Freddy_Hutagalung@d1.lcl | F19: 86252, 302 | G19: AHL | H19: User | I19: 1
A20: 352 | B20: Iwan Budiman | C20: =VLOOKUP("*"&B:B&"*",HC_0220!C:C,1,FALSE) -> Iwan Budiman | D20: Iwan_budiman | E20: Iwan_Budiman@ptadindo.com | F20: 86252, 222 | G20: AHL | H20: User | I20: 1
A21: 353 | B21: Hery Widayat | C21: =VLOOKUP("*"&B:B&"*",HC_0220!C:C,1,FALSE) -> Hery Widayat | D21: Hery_Widayat | E21: hery_widayat@d1.lcl | G21: AHL | H21: User | I21: 1
A22: 354 | B22: Lasmaria Manik | C22: =VLOOKUP("*"&B:B&"*",HC_0220!C:C,1,FALSE) -> Lasmaria Manik | D22: Lasmaria_Manik | E22: Lasmaria_Manik@ptadindo.com | F22: 86252, 143 | G22: AHL | H22: User | I22: 1
A23: 355 | B23: Eka Sirait | C23: Eka Tjlm Sirait | D23: Eka_sirait | E23: Eka_Sirait@ptadindo.com | F23: 86252, 167 | G23: AHL | H23: User | I23: 1
A24: 357 | B24: Ferdongan Damanik | C24: =VLOOKUP("*"&B:B&"*",HC_0220!C:C,1,FALSE) -> Ferdongan Damanik | D24: Ferdongan_Damanik | E24: Ferdongan_Damanik@d1.lcl | G24: AHL | H24: User | I24: 1
A25: 358 | B25: Rudi Lumele | C25: Rudy Lumele | D25: Rudi_Lumele | E25: Rudi_Lumele@d1.lcl | G25: AHL | H25: User | I25: 1
A26: 359 | B26: Franki Sinaga | C26: =VLOOKUP("*"&B:B&"*",HC_0220!C:C,1,FALSE) -> Franki Sinaga | D26: Franki_Sinaga | E26: Franki_Sinaga@d1.lcl | G26: AHL | H26: User | I26: 1
A27: 360 | B27: Saravana Kumar | C27: =VLOOKUP("*"&B:B&"*",HC_0220!C:C,1,FALSE) -> Saravana Kumar | D27: Kumar_A | E27: Kumar_A@ptadindo.com | F27: 86252, 201 | G27: AHL | H27: User | I27: 1
A28: 361 | B28: Deni Amroni Nainggolan | C28: =VLOOKUP("*"&B:B&"*",HC_0220!C:C,1,FALSE) -> #N/A | D28: Deni_Nainggolan | E28: Deni_Nainggolan@ptadindo.com | F28: 86252, 302 | G28: AHL | H28: User | I28: 1
A29: 362 | B29: Ali Bahran | C29: =VLOOKUP("*"&B:B&"*",HC_0220!C:C,1,FALSE) -> Ali Bahran Dalimunthe | D29: Ali_Bahran | E29: Ali_Bahran@ptadindo.com | G29: AHL | H29: User | I29: 1
A30: 363 | B30: Nalom MP Butar Butar | C30: Nalom MP Butarbutar | D30: Nalom_mp | E30: Nalom_MP@ptadindo.com | F30: 86252, 115 | G30: AHL | H30: User | I30: 1
A31: 364 | B31: Tino Margi | C31: =VLOOKUP("*"&B:B&"*",HC_0220!C:C,1,FALSE) -> Tino Margi | D31: Tino_Margi | E31: Tino_Margi@d1.lcl | G31: AHL | H31: User | I31: 1
A32: 365 | B32: Totok Suwadi | C32: =VLOOKUP("*"&B:B&"*",HC_0220!C:C,1,FALSE) -> Totok Suwadi | D32: Totok_Suwadi | E32: Totok_Suwadi@d1.lcl | F32: 86252, 402 | G32: AHL | H32: User | I32: 1
A33: 366 | B33: Henry H. Panggabean | C33: Henry Handus Panggabean | D33: Henry_Panggabean | E33: Henry_Panggabean@d1.lcl | G33: AHL | H33: User | I33: 1
A34: 367 | B34: Ign Priantoro | C34: Ignasius Erlangga Priantoro | D34: Ign_Priantoro | E34: Ign_Priantoro@ptadindo.com | F34: 86250, 215 | G34: AHL | H34: User | I34: 1
A35: 368 | B35: Catherin | C35: =VLOOKUP("*"&B:B&"*",HC_0220!C:C,1,FALSE) -> Catherin Buntu | D35: Catherin | E35: Catherin@d1.lcl | F35: 86252, 401 | G35: AHL | H35: User | I35: 1
A36: 369 | B36: Arsita | C36: =VLOOKUP("*"&B:B&"*",HC_0220!C:C,1,FALSE) -> Arsita | D36: Arsita | E36: Arsita@ptadindo.com | F36: 86252, 157 | G36: AHL | H36: User | I36: 1
A37: 370 | B37: Tumbur ButarButar | C37: Tumbur Butar-Butar | D37: Tumbur_ButarButar | E37: Tumbur_ButarButar@d1.lcl | F37: 86252 77 2112 | G37: AHL | H37: User | I37: 1
A38: 371 | B38: Nasrunlari E. | C38: =VLOOKUP("*"&B:B&"*",HC_0220!C:C,1,FALSE) -> #N/A | D38: Nasrunlari | E38: Nasrunlari@d1.lcl | F38: 86252, 202 | G38: AHL | H38: User | I38: 1
A39: 373 | B39: Security AHL Sesayap | C39: =VLOOKUP("*"&B:B&"*",HC_0220!C:C,1,FALSE) -> #N/A | D39: Sec_AHL_Sesayap | E39: Sec_AHL_Sesayap@d1.lcl | G39: AHL | H39: User | I39: 1
A40: 374 | B40: Henry Yunus | C40: =VLOOKUP("*"&B:B&"*",HC_0220!C:C,1,FALSE) -> Henry Yunus | D40: Henry_Yunus | E40: Henry_Yunus@d1.lcl | G40: AHL | H40: User | I40: 1
...

Sheet Sheet1
F3: 13000005 | G3: KPSI- Finance Accounting
F4: 13000006 | G4: KPSI-Procurement,KDU
F5: 13000082 | G5: IHM-Operational MO, KF
F6: 13000083 | G6: IHM-Planning MO, KF
F7: 13000084 | G7: IHM-Wood Supply MO, KF
F8: 13000085 | G8: IHM-Road Maintenance & In
F9: 13000086 | G9: IHM-Plantation MO, KF
F10: 13000087 | G10: IHM-Sustainability MO, KF
F11: 13000088 | G11: IHM-F&A MO, KF
F12: 13000089 | G12: IHM-Common Service MO, KF
F13: 13000090 | G13: IHM-HR Operation MO, KF
F14: 13000091 | G14: IHM-BDU Quarry Sepaku, KF
... F100: 70544651 | G100: IHM-Harvesting QA&QC, KF
